<?xml version="1.0" ?>
<robot name="dummy-ros2" xmlns:xacro="http://www.ros.org/wiki/xacro">

<xacro:include filename="$(find dummy-ros2_description)/urdf/materials.xacro" />
<xacro:include filename="$(find dummy-ros2_description)/urdf/dummy-ros2.trans" />
<xacro:include filename="$(find dummy-ros2_description)/urdf/dummy-ros2.gazebo" />
<link name="world" />
<joint name="world_joint" type="fixed">
  <parent link="world" />
  <child link = "base_link" />
  <origin xyz="0.0 0.0 0.0" rpy="3.1415926536 3.1415926536 0.0" />
</joint>

<link name="base_link">
  <inertial>
    <origin xyz="-0.014999999232056279 -0.08246735477620445 0.032605452564980174" rpy="0 0 0"/>
    <mass value="2.718238265964926"/>
    <inertia ixx="0.005512" iyy="0.005791" izz="0.005729" ixy="0.0" iyz="7.1e-05" ixz="-0.0"/>
  </inertial>
  <visual>
    <origin xyz="0 0 0" rpy="0 0 0"/>
    <geometry>
      <mesh filename="file://$(find dummy-ros2_description)/meshes/base_link.stl" scale="0.001 0.001 0.001"/>
    </geometry>
    <material name="silver"/>
  </visual>
  <collision>
    <origin xyz="0 0 0" rpy="0 0 0"/>
    <geometry>
      <mesh filename="file://$(find dummy-ros2_description)/meshes/base_link.stl" scale="0.001 0.001 0.001"/>
    </geometry>
  </collision>
</link>

<link name="link1_1_1">
  <inertial>
    <origin xyz="-0.009839298045306172 -0.009665764146279704 0.016866258077055246" rpy="0 0 0"/>
    <mass value="0.41661715346354466"/>
    <inertia ixx="0.00024" iyy="0.000197" izz="0.000294" ixy="-7.9e-05" iyz="7e-05" ixz="4.5e-05"/>
  </inertial>
  <visual>
    <origin xyz="0.015 0.079017 -0.0825" rpy="0 0 0"/>
    <geometry>
      <mesh filename="file://$(find dummy-ros2_description)/meshes/link1_1_1.stl" scale="0.001 0.001 0.001"/>
    </geometry>
    <material name="silver"/>
  </visual>
  <collision>
    <origin xyz="0.015 0.079017 -0.0825" rpy="0 0 0"/>
    <geometry>
      <mesh filename="file://$(find dummy-ros2_description)/meshes/link1_1_1.stl" scale="0.001 0.001 0.001"/>
    </geometry>
  </collision>
</link>

<link name="link2_1_1">
  <inertial>
    <origin xyz="0.01589274835546871 -0.0002176337870416073 0.07388173251947006" rpy="0 0 0"/>
    <mass value="0.8248343726921459"/>
    <inertia ixx="0.003112" iyy="0.003172" izz="0.000413" ixy="-3e-06" iyz="1.8e-05" ixz="0.000549"/>
  </inertial>
  <visual>
    <origin xyz="0.032 0.114017 -0.12" rpy="0 0 0"/>
    <geometry>
      <mesh filename="file://$(find dummy-ros2_description)/meshes/link2_1_1.stl" scale="0.001 0.001 0.001"/>
    </geometry>
    <material name="silver"/>
  </visual>
  <collision>
    <origin xyz="0.032 0.114017 -0.12" rpy="0 0 0"/>
    <geometry>
      <mesh filename="file://$(find dummy-ros2_description)/meshes/link2_1_1.stl" scale="0.001 0.001 0.001"/>
    </geometry>
  </collision>
</link>

<link name="link3_1_1">
  <inertial>
    <origin xyz="-0.00556719985211092 -0.0008849434541333689 0.032857930319999507" rpy="0 0 0"/>
    <mass value="0.334446749870256"/>
    <inertia ixx="0.000242" iyy="0.000299" izz="0.000122" ixy="-3e-06" iyz="5e-06" ixz="7.5e-05"/>
  </inertial>
  <visual>
    <origin xyz="-0.0 0.114017 -0.266" rpy="0 0 0"/>
    <geometry>
      <mesh filename="file://$(find dummy-ros2_description)/meshes/link3_1_1.stl" scale="0.001 0.001 0.001"/>
    </geometry>
    <material name="silver"/>
  </visual>
  <collision>
    <origin xyz="-0.0 0.114017 -0.266" rpy="0 0 0"/>
    <geometry>
      <mesh filename="file://$(find dummy-ros2_description)/meshes/link3_1_1.stl" scale="0.001 0.001 0.001"/>
    </geometry>
  </collision>
</link>

<link name="link4_1_1">
  <inertial>
    <origin xyz="0.004619417619842917 -0.05852434935618758 -1.7565479792924776e-07" rpy="0 0 0"/>
    <mass value="0.38229981321745393"/>
    <inertia ixx="0.000681" iyy="7.7e-05" izz="0.000663" ixy="-3e-06" iyz="0.0" ixz="-0.0"/>
  </inertial>
  <visual>
    <origin xyz="0.017 0.131517 -0.318" rpy="0 0 0"/>
    <geometry>
      <mesh filename="file://$(find dummy-ros2_description)/meshes/link4_1_1.stl" scale="0.001 0.001 0.001"/>
    </geometry>
    <material name="silver"/>
  </visual>
  <collision>
    <origin xyz="0.017 0.131517 -0.318" rpy="0 0 0"/>
    <geometry>
      <mesh filename="file://$(find dummy-ros2_description)/meshes/link4_1_1.stl" scale="0.001 0.001 0.001"/>
    </geometry>
  </collision>
</link>

<link name="link5_1_1">
  <inertial>
    <origin xyz="0.0009057999155941757 -0.02906083845119581 -2.2799463705869272e-08" rpy="0 0 0"/>
    <mass value="0.14119342984175104"/>
    <inertia ixx="0.000118" iyy="3.6e-05" izz="0.000122" ixy="2.5e-05" iyz="0.0" ixz="0.0"/>
  </inertial>
  <visual>
    <origin xyz="0.0346 0.234017 -0.318" rpy="0 0 0"/>
    <geometry>
      <mesh filename="file://$(find dummy-ros2_description)/meshes/link5_1_1.stl" scale="0.001 0.001 0.001"/>
    </geometry>
    <material name="silver"/>
  </visual>
  <collision>
    <origin xyz="0.0346 0.234017 -0.318" rpy="0 0 0"/>
    <geometry>
      <mesh filename="file://$(find dummy-ros2_description)/meshes/link5_1_1.stl" scale="0.001 0.001 0.001"/>
    </geometry>
  </collision>
</link>

<link name="link6_1_1">
  <inertial>
    <origin xyz="-0.0003068043075796188 0.01033562863039611 -3.814698834592178e-09" rpy="0 0 0"/>
    <mass value="0.21609201162441805"/>
    <inertia ixx="3.1e-05" iyy="4.2e-05" izz="3.2e-05" ixy="1e-06" iyz="-0.0" ixz="-0.0"/>
  </inertial>
  <visual>
    <origin xyz="0.016 0.290517 -0.318" rpy="0 0 0"/>
    <geometry>
      <mesh filename="file://$(find dummy-ros2_description)/meshes/link6_1_1.stl" scale="0.001 0.001 0.001"/>
    </geometry>
    <material name="silver"/>
  </visual>
  <collision>
    <origin xyz="0.016 0.290517 -0.318" rpy="0 0 0"/>
    <geometry>
      <mesh filename="file://$(find dummy-ros2_description)/meshes/link6_1_1.stl" scale="0.001 0.001 0.001"/>
    </geometry>
  </collision>
</link>

<joint name="Joint1" type="revolute">
  <origin xyz="-0.015 -0.079017 0.0825" rpy="0 0 0"/>
  <parent link="base_link"/>
  <child link="link1_1_1"/>
  <axis xyz="0.0 0.0 1.0"/>
  <limit 
    lower="-3.141593"
    upper="3.141593"
    effort="150"
    velocity="3.15"/>
</joint>

<joint name="Joint2" type="revolute">
  <origin xyz="-0.017 -0.035 0.0375" rpy="0 0 0"/>
  <parent link="link1_1_1"/>
  <child link="link2_1_1"/>
  <axis xyz="1.0 0.0 -0.0"/>
  <limit
    lower="-1.308997"
    upper="1.570796"
    effort="150"
    velocity="3.15" />
</joint>

<joint name="Joint3" type="revolute">
  <origin xyz="0.032 0.0 0.146" rpy="0 0 0"/>
  <parent link="link2_1_1"/>
  <child link="link3_1_1"/>
  <axis xyz="1.0 -0.0 -0.0"/>
  <limit
    lower="-1.570796"
    upper="1.570796"
    effort="150"
    velocity="3.15" />
</joint>

<joint name="Joint4" type="revolute">
  <origin xyz="-0.017 -0.0175 0.052" rpy="0 0 0"/>
  <parent link="link3_1_1"/>
  <child link="link4_1_1"/>
  <axis xyz="0.0 -1.0 0.0"/>
  <limit
    lower="-3.14"
    upper="3.14"
    effort="150"
    velocity="3.15" />
</joint>

<joint name="Joint5" type="revolute">
  <origin xyz="-0.0176 -0.1025 0.0" rpy="0 0 0"/>
  <parent link="link4_1_1"/>
  <child link="link5_1_1"/>
  <axis xyz="-1.0 -0.0 0.0"/>
  <limit
    lower="-1.570796"
    upper="1.570796"
    effort="150"
    velocity="3.15" />
</joint>

<joint name="Joint6" type="revolute">
  <origin xyz="0.0186 -0.0565 0.0" rpy="0 0 0"/>
  <parent link="link5_1_1"/>
  <child link="link6_1_1"/>
  <axis xyz="0.0 1.0 -0.0"/>
  <limit
    lower="-3.14"
    upper="3.14"
    effort="150"
    velocity="3.15" />
</joint>

</robot>
